Workbook

Sheet 0_README
A1: LoanOS India — Tenant Cost & Pricing Model (full loan lifecycle)
A2: Bottom-up unit economics for a multi-tenant, RBI-compliance-first lending platform. Origination, servicing, collections and closure across all 21 journeys and all 115 integrations.
A4: What this model answers
B5: 1. What does it cost to run one tenant for one month, to originate one loan, and to SERVICE it to closure?
B6: 2. How does that change across the 21 journeys? Sheet 14 computes it live.
B7: 3. What must we charge to hit a target gross margin — on origination AND on the book?
B8: 4. At what volume does a tenant break even, and how does year 1 differ from the steady-state book?
A10: Cost classes
B11: Class U — unit cost, fires N times against a countable basis (application, loan-month, EMI, closure, collection event).
B12: Class R — recurring subscription, scales with a QUANTITY driver (devices, branches, seats, partners, feeds).
B13: This class is why a branch-heavy tenant can cost more than a digital one at ten times the volume.
B14: Class P — platform fixed cost, allocated across tenants (cloud, governance, support).
A16: Coverage
B17: All 21 canonical product journeys.
B18: All 115 INT-* integrations: 96 carry an explicit priced driver; 19 are deliberately absorbed by the cloud,
B19: governance or service sheets, or are internal capabilities with no external unit price.
B20: Sheet 16 lists every one of the 115 with its treatment. Nothing is silently omitted.
B21: LOS lifecycle stages 1-12: application_capture through closure.
A23: How to use it
B24: Step 1 Fill only the BLUE cells on 1_Inputs. That includes the quantity drivers that size the recurring class.
B25: Step 2 Replace 2_RateCard_Unit and 3_RateCard_Recurring with signed vendor prices. Nothing else matters as much.
B26: Step 3 Calibrate 6_Funnel_And_Lifetime — conversion, tenor, prepayment, delinquency — to the tenant's own history.
B27: Step 4 Read 12_Tenant_PnL for margin and break-even, and 13_Price_Card for the quote.
B28: Step 5 Use 14_Journey_Economics to price journey by journey. Never quote one blended price across the spread.
A30: Colour legend
B31: BLUE text = hardcoded input or scenario lever. Safe to edit.
B32: BLACK text = formula on this sheet. GREEN text = link to another sheet. Do not overwrite either.
B33: YELLOW fill = key assumption you are expected to challenge.
B34: ORANGE fill = no published price anchor exists; the number is a placeholder pending a vendor quotation.
A36: Honesty note — read before quoting anyone
B37: Every rupee figure here is a PLACEHOLDER ASSUMPTION. Only three priced drivers have a dated public price in
B38: docs/architecture/integration-vendor-procurement-catalog.md (MSG91, Finvu, Cashfree). Every other line there
B39: is explicitly RFQ, which is why most of this rate card is Medium or Low confidence.
B41: The funnel, tenor, prepayment and delinquency profiles are industry-shaped guesses, not measured LoanOS data.
B42: Origination cost scales inversely with the funded rate; servicing cost scales with effective life; collections
B43: cost scales with the delinquency profile. All three are unmeasured. Stand up the usage meter before repricing.
A45: Repo anchors
B46: 21 journeys and maturity docs/product/product-journey-platform-depth.json
B47: LOS lifecycle stages docs/architecture/composed-product-journey-lifecycle.md
B48: All 115 INT-* integrations docs/architecture/platform-module-integration-api-map.md
...

Sheet 1_Inputs
A1: 1 — Deal inputs
A2: Edit BLUE cells only. Everything downstream recalculates from here.
A4: Deal identity
A6: Tenant / regulated entity name | B6: Example NBFC Ltd | C6: Free text — appears on the price card.
A7: Regulated entity type | B7: NBFC-ICC | C7: NBFC / NBFC-MFI / HFC / SFB / Bank / LSP. Drives regulatory scope.
A8: Contract term (months) | B8: 36 | C8: Amortises onboarding cost and fee.
A9: Live tenants on platform | B9: 12 | C9: Denominator for equal-share governance allocation.
A10: Platform annual funded loans (all tenants) | B10: 900000 | C10: Denominator for volume-weighted governance allocation.
A11: Deployment and service
A13: Deployment model | B13: shared_multi_tenant | C13: SAAS_DEPLOYMENT_MODELS in saas-deployment-blueprints.js.
A14: Support tier | B14: Standard | C14: Drives sheet 11.
A15: Governance allocation basis | B15: Blended 50/50 | C15: How platform compliance cost spreads across tenants.
A16: Journey, volume and book
A18: Primary journey | B18: personal_loan | C18: One of the 21 canonical journeys. Price each separately.
A19: Monthly applications STARTED | B19: 4000 | C19: Entering application_capture — not approved or funded loans.
A20: Rate card scenario | B20: Base | C20: Low / Base / High column on both rate cards.
A21: Book maturity | B21: Steady state | C21: Year 1 = ramping book, little servicing cost or revenue. Steady state = originations equal closures. Quote multi-year deals on steady state.
A22: Average ticket override (₹, 0 = journey default) | B22: 0 | C22: Set only if this tenant's ticket differs.
A23: Commercial levers
A25: Target gross margin % | B25: 0.62 | C25: Sheet 13 solves for the per-funded-loan fee that achieves this.
A26: Pass-through handling markup % | B26: 0.08 | C26: Markup on rebilled provider cost. 0% = pure pass-through.
A27: Platform fee (₹ per month) | B27: 350000 | C27: Fixed subscription. Recovers the per-tenant cost floor.
A28: Fee per DECISIONED application (₹) | B28: 12 | C28: Metered at credit_decision — resistant to junk-lead gaming.
A29: Fee per FUNDED loan (₹) | B29: 900 | C29: Origination fee, charged on disbursement.
A30: LMS fee per ACTIVE loan per month (₹) | B30: 14 | C30: Servicing fee on the book — what pays for the loan's whole life.
A31: One-time onboarding fee charged (₹) | B31: 750000 | C31: Compare against modelled onboarding cost on sheet 11.
A33: Quantity drivers — these size the RECURRING cost class (sheet 3)
A34: Recurring cost does not scale with loan volume. It scales with these. A tenant with 25 branches and 120 field devices carries that cost whether it originates 200 loans a month or 20,000.
A36: Basis key | B36: Quantity driver | C36: Quantity | D36: Unit
A37: field_devices_month | B37: Field devices under management | C37: 120 | D37: per device / month
A38: branches_month | B38: Branches / territories | C38: 25 | D38: per branch / month
A39: staff_seats_month | B39: Staff seats (all workspaces) | C39: 260 | D39: per seat / month
A40: bi_seats_month | B40: BI / analytics seats | C40: 15 | D40: per seat / month
A41: partners_month | B41: Active partners / LSPs / DSAs | C41: 40 | D41: per partner / month
A42: vendor_panel_month | B42: Empanelled valuers, advocates, agencies | C42: 35 | D42: per vendor / month
A43: bank_accounts_month | B43: Operating, escrow and collection accounts | C43: 8 | D43: per account / month
A44: languages_year | B44: Approved vernacular languages | C44: 6 | D44: per language / year
A45: reference_feeds_year | B45: Reference data feeds subscribed | C45: 4 | D45: per feed / year
A46: governed_models_year | B46: Governed models under monitoring | C46: 7 | D46: per model / year
A47: vector_gb_month | B47: Agent knowledge index (GB) | C47: 40 | D47: per GB / month
...

Sheet 2_RateCard_Unit
A1: 2 — Unit cost rate card (Class U)
A2: One row per per-event cost driver across the whole loan lifecycle, mapped to its INT-* integration ID.
A4: Driver ID | B4: Cost driver | C4: INT ID | D4: Fires at (LOS stage / lifetime basis) | E4: Unit | F4: Low ₹ | G4: Base ₹ | H4: High ₹ | I4: Attempts | J4: Confidence | K4: Pass-through? | L4: Vendor / assumption note | M4: Public price anchor
A5: D01 | B5: Mobile/email OTP + delivery (DLT SMS / WhatsApp) | C5: INT-CUS-01 | D5: application_capture | E5: per OTP sent | F5: 0.16 | G5: 0.2 | H5: 0.3 | I5: 1.6 | J5: High | K5: No | L5: MSG91 public list: Rs 0.25 at 5k/mo, Rs 0.18 at 30k, Rs 0.16 at ~1m, +18% GST. Add DLT/operator charge. | M5: MSG91 published list price (procurement catalogue §C)
A6: D02 | B6: Lead capture, dedupe and CRM sync | C6: INT-CUS-02 | D6: application_capture | E6: per lead | F6: 0 | G6: 0.5 | H6: 2 | I6: 1 | J6: Low | K6: No | L6: Zero if internal-only; priced if an external CRM seat/API is in the path. | M6: RFQ — no public price; placeholder pending vendor quotation
A7: D03 | B7: Document upload + malware/DLP scan | C7: INT-CUS-04 | D7: application_capture | E7: per document | F7: 0.2 | G7: 0.6 | H7: 1.5 | I7: 1.05 | J7: Medium | K7: No | L7: Object storage PUT + AV/DLP scan. Excludes long-run retention (see 6_Cloud_Cost). | M7: RFQ — no public price; placeholder pending vendor quotation
A8: D04 | B8: DigiLocker consent + issued-document fetch | C8: INT-CUS-05 | D8: application_capture | E8: per fetch | F8: 2 | G8: 6 | H8: 12 | I8: 1.2 | J8: Medium | K8: Yes | L8: Aggregator fee. INT-CUS-05 is currently Missing in the integration map. | M8: RFQ — no public price; placeholder pending vendor quotation
A9: D05 | B9: Device / SIM / IP fraud signal | C9: INT-LOS-09 | D9: application_capture | E9: per check | F9: 3 | G9: 7 | H9: 15 | I9: 1.02 | J9: Medium | K9: Yes | L9: Fraud intelligence vendor; priced per device fingerprint lookup. | M9: RFQ — no public price; placeholder pending vendor quotation
A10: D06 | B10: PAN verification (Protean/NSDL) | C10: INT-LOS-01 | D10: kyc_aml | E10: per verification | F10: 1.5 | G10: 3 | H10: 6 | I10: 1.05 | J10: High | K10: Yes | L10: Well-benchmarked; aggregator markup over Protean base. | M10: RFQ — no public price; placeholder pending vendor quotation
A11: D07 | B11: Aadhaar offline XML / QR / KUA eKYC | C11: INT-LOS-01 | D11: kyc_aml | E11: per eKYC | F11: 3 | G11: 8 | H11: 20 | I11: 1.25 | J11: Medium | K11: Yes | L11: UIDAI auth/eKYC fee plus AUA/KUA aggregator markup. Permitted-use only. | M11: RFQ — no public price; placeholder pending vendor quotation
A12: D08 | B12: CKYC search + record download (CERSAI) | C12: INT-LOS-02 | D12: kyc_aml | E12: per record | F12: 0.5 | G12: 1.5 | H12: 3 | I12: 1.1 | J12: Medium | K12: Yes | L12: CERSAI download charge; low unit cost, high volume. | M12: RFQ — no public price; placeholder pending vendor quotation
A13: D09 | B13: V-CIP session (platform + agent handling time) | C13: INT-LOS-03 | D13: kyc_aml | E13: per session | F13: 40 | G13: 85 | H13: 160 | I13: 1.3 | J13: Medium | K13: Yes | L13: Largest single KYC cost. Agent minutes usually exceed the platform fee. | M13: RFQ — no public price; placeholder pending vendor quotation
A14: D10 | B14: Liveness / face match / spoof detection | C14: INT-LOS-03 | D14: kyc_aml | E14: per check | F14: 3 | G14: 7 | H14: 15 | I14: 1.2 | J14: Medium | K14: Yes | L14: Bundled into V-CIP by some vendors — avoid double counting. | M14: RFQ — no public price; placeholder pending vendor quotation
A15: D11 | B15: AML / PEP / sanctions / adverse media screen | C15: INT-LOS-09 | D15: kyc_aml | E15: per screen | F15: 2 | G15: 6 | H15: 15 | I15: 1.02 | J15: Medium | K15: Yes | L15: Per subject screened; joint applicants and UBOs multiply this. | M15: RFQ — no public price; placeholder pending vendor quotation
A16: D12 | B16: KYB — GSTIN / Udyam / MCA entity verification | C16: INT-LOS-04 | D16: kyc_aml | E16: per entity | F16: 5 | G16: 18 | H16: 45 | I16: 1.08 | J16: Low | K16: Yes | L16: INT-LOS-04 is Missing today; assumption is aggregator list price. | M16: RFQ — no public price; placeholder pending vendor quotation
... A67: C09 | B67: Repossession and yard management | C67: INT-COLAT-07 | D67: per_collection_event | E67: per repossession | F67: 3000 | G67: 9000 | H67: 25000 | I67: 1 | J67: Low | K67: Yes | L67: Asset-finance journeys: work order, inventory/condition, movement, yard fees and release. | M67: RFQ — no public price; placeholder pending vendor quotation
B69: Row groups — green = origination (LOS), blue = servicing (LMS/closure), orange = collections and recovery.
B70: SOURCE OF TRUTH: docs/architecture/integration-vendor-procurement-catalog.md carries a dated public price for only three lines below; every other line there is explicitly RFQ. Do not quote from an orange anchor cell.

Sheet 3_RateCard_Recurring
A1: 3 — Recurring cost rate card (Class R)
A2: Subscriptions and per-seat / per-device / per-partner costs. These scale with the QUANTITY DRIVERS on sheet 1, not with loan volume — which is why they decide whether a small tenant is viable.
A4: ID | B4: Recurring cost driver | C4: INT ID(s) | D4: Quantity basis | E4: Qty | F4: Low ₹ | G4: Base ₹ | H4: High ₹ | I4: Confidence | J4: Pass-through? | K4: Periods / yr | L4: ₹ per year | M4: Note
A5: R01 | B5: Mobile device management licence | C5: INT-CUS-06 | D5: field_devices_month | E5: =IFERROR(INDEX('1_Inputs'!$C$37:$C$49,MATCH($D5,'1_Inputs'!$A$37:$A$49,0)),0) | F5: 80 | G5: 150 | H5: 400 | I5: Low | J5: No | K5: 12 | L5: =E5*INDEX($F5:$H5,'1_Inputs'!$B$54)*K5 | M5: Per enrolled field device per month. MDM enrol/attest/compliance/wipe. Live adapter missing today.
A6: R02 | B6: Device attestation and certificate lifecycle | C6: INT-PLT-13 | D6: field_devices_month | E6: =IFERROR(INDEX('1_Inputs'!$C$37:$C$49,MATCH($D6,'1_Inputs'!$A$37:$A$49,0)),0) | F6: 20 | G6: 35 | H6: 90 | I6: Low | J6: No | K6: 12 | L6: =E6*INDEX($F6:$H6,'1_Inputs'!$B$54)*K6 | M6: Certificate issue/rotate/revoke per managed device. Often bundled with R01 — check before adding both.
A7: R03 | B7: Branch, agent and territory master sync | C7: INT-CUS-03 | D7: branches_month | E7: =IFERROR(INDEX('1_Inputs'!$C$37:$C$49,MATCH($D7,'1_Inputs'!$A$37:$A$49,0)),0) | F7: 100 | G7: 250 | H7: 700 | I7: Low | J7: No | K7: 12 | L7: =E7*INDEX($F7:$H7,'1_Inputs'!$B$54)*K7 | M7: Agent/branch/territory/credential/capacity master sync with change and revoke totals.
A8: R04 | B8: Vernacular content production and approval | C8: INT-CUS-08 | D8: languages_year | E8: =IFERROR(INDEX('1_Inputs'!$C$37:$C$49,MATCH($D8,'1_Inputs'!$A$37:$A$49,0)),0) | F8: 15000 | G8: 35000 | H8: 90000 | I8: Low | J8: No | K8: 1 | L8: =E8*INDEX($F8:$H8,'1_Inputs'!$B$54)*K8 | M8: Per approved language per product version per year. RBI requires KFS and key notices in a language the borrower understands — this is a regulatory cost, not a UX nicety. Dispatch is separately metered (D27).
A9: R05 | B9: Reference data feeds (benchmarks, calendars, indices) | C9: INT-RSK-06 | D9: reference_feeds_year | E9: =IFERROR(INDEX('1_Inputs'!$C$37:$C$49,MATCH($D9,'1_Inputs'!$A$37:$A$49,0)),0) | F9: 50000 | G9: 150000 | H9: 450000 | I9: Low | J9: Yes | K9: 1 | L9: =E9*INDEX($F9:$H9,'1_Inputs'!$B$54)*K9 | M9: Benchmark rates, business calendars, geography, industry and collateral indices with effective date and checksum.
A10: R06 | B10: Model operations: drift, bias and performance feeds | C10: INT-RSK-05 | D10: governed_models_year | E10: =IFERROR(INDEX('1_Inputs'!$C$37:$C$49,MATCH($D10,'1_Inputs'!$A$37:$A$49,0)),0) | F10: 40000 | G10: 90000 | H10: 250000 | I10: Low | J10: No | K10: 1 | L10: =E10*INDEX($F10:$H10,'1_Inputs'!$B$54)*K10 | M10: Per governed model per year. Registry/artifact/feature feed plus drift and bias metrics.
A11: R07 | B11: Agent knowledge index storage and refresh | C11: INT-RSK-08 | D11: vector_gb_month | E11: =IFERROR(INDEX('1_Inputs'!$C$37:$C$49,MATCH($D11,'1_Inputs'!$A$37:$A$49,0)),0) | F11: 150 | G11: 300 | H11: 800 | I11: Low | J11: No | K11: 12 | L11: =E11*INDEX($F11:$H11,'1_Inputs'!$B$54)*K11 | M11: Per GB-month of approved knowledge index, including re-embedding on source change.
A12: R08 | B12: HRMS worker, position and JML feed | C12: INT-LWS-01 | D12: staff_seats_month | E12: =IFERROR(INDEX('1_Inputs'!$C$37:$C$49,MATCH($D12,'1_Inputs'!$A$37:$A$49,0)),0) | F12: 15 | G12: 30 | H12: 80 | I12: Low | J12: No | K12: 12 | L12: =E12*INDEX($F12:$H12,'1_Inputs'!$B$54)*K12 | M12: Worker/position/manager/branch/leave/delegation deltas that drive staff authority and routing.
A13: R09 | B13: Enterprise IdP and SCIM provisioning | C13: INT-LWS-02 | D13: staff_seats_month | E13: =IFERROR(INDEX('1_Inputs'!$C$37:$C$49,MATCH($D13,'1_Inputs'!$A$37:$A$49,0)),0) | F13: 40 | G13: 110 | H13: 300 | I13: Medium | J13: No | K13: 12 | L13: =E13*INDEX($F13:$H13,'1_Inputs'!$B$54)*K13 | M13: Per active user per month, plus MFA/conditional-access and governance tier. Procurement catalogue marks this RFQ.
A14: R10 | B14: Task and escalation notifications (staff) | C14: INT-LWS-03 | D14: staff_seats_month | E14: =IFERROR(INDEX('1_Inputs'!$C$37:$C$49,MATCH($D14,'1_Inputs'!$A$37:$A$49,0)),0) | F14: 10 | G14: 20 | H14: 60 | I14: Low | J14: No | K14: 12 | L14: =E14*INDEX($F14:$H14,'1_Inputs'!$B$54)*K14 | M14: Email/SMS/WhatsApp/voice/pager to staff, with delivery callbacks. Distinct from borrower communications.
A15: R11 | B15: Evidence, committee and minutes vault | C15: INT-LWS-04 | D15: staff_seats_month | E15: =IFERROR(INDEX('1_Inputs'!$C$37:$C$49,MATCH($D15,'1_Inputs'!$A$37:$A$49,0)),0) | F15: 20 | G15: 40 | H15: 120 | I15: Low | J15: No | K15: 12 | L15: =E15*INDEX($F15:$H15,'1_Inputs'!$B$54)*K15 | M15: DMS upload/version/download, legal hold, signed minutes and manifest.
A16: R12 | B16: External work-order routing platform | C16: INT-LWS-05 | D16: vendor_panel_month | E16: =IFERROR(INDEX('1_Inputs'!$C$37:$C$49,MATCH($D16,'1_Inputs'!$A$37:$A$49,0)),0) | F16: 100 | G16: 200 | H16: 600 | I16: Low | J16: No | K16: 12 | L16: =E16*INDEX($F16:$H16,'1_Inputs'!$B$54)*K16 | M16: Per empanelled valuer/advocate/agency/custodian/insurer per month. The orders themselves are metered elsewhere.
... A41: R37 | B41: Tenant billing: meter, invoice, tax, payment | C41: INT-PLT-12, INT-ADM-08 | D41: tenant_month | E41: =IFERROR(INDEX('1_Inputs'!$C$37:$C$49,MATCH($D41,'1_Inputs'!$A$37:$A$49,0)),0) | F41: 6000 | G41: 12000 | H41: 35000 | I41: Low | J41: No | K41: 12 | L41: =E41*INDEX($F41:$H41,'1_Inputs'!$B$54)*K41 | M41: DOES NOT EXIST YET. INT-ADM-08 records 'Commercial controls only; no billing/tax/payment provider'. This line is what it will cost to run the meter this whole model depends on.
B42: TOTAL recurring ₹ per year | L42: =SUM(L5:L41)
B43: of which pass-through | L43: =SUMIF($J$5:$J$41,"Yes",L5:L41)
B44: of which platform-borne | L44: =SUMIF($J$5:$J$41,"No",L5:L41)
A46: One-time admission cost (INT-ADM-*) — flows into onboarding
A47: ID | B47: Admission cost driver | C47: INT ID | F47: Low ₹ | G47: Base ₹ | H47: High ₹ | I47: Confidence | L47: ₹ one-time | M47: Note
A48: A01 | B48: Signup contact verification and invitations | C48: INT-ADM-01 | F48: 500 | G48: 1200 | H48: 4000 | I48: Low | L48: =INDEX($F48:$H48,'1_Inputs'!$B$54) | M48: Work-email and mobile OTP, invite/expiry, DLT template, delivery/bounce.
A49: A02 | B49: Legal-entity and tax identity verification | C49: INT-ADM-02 | F49: 2000 | G49: 4500 | H49: 12000 | I49: Low | L49: =INDEX($F49:$H49,'1_Inputs'!$B$54) | M49: MCA company/LLP master, CIN/LLPIN, directors/signatories, GSTIN, PAN/TAN, Udyam status and change evidence.
A50: A03 | B50: Regulated-entity authority verification | C50: INT-ADM-03 | F50: 1000 | G50: 2500 | H50: 8000 | I50: Low | L50: =INDEX($F50:$H50,'1_Inputs'!$B$54) | M50: RBI and other-authority current/cancelled lists, licence/CoR category and layer.
A51: A04 | B51: Representative authority and signature validation | C51: INT-ADM-04 | F51: 3000 | G51: 7000 | H51: 20000 | I51: Low | L51: =INDEX($F51:$H51,'1_Inputs'!$B$54) | M51: Director/DIN/signatory match, board resolution, DSC/eSign chain, CRL/OCSP and long-term validation.
A52: A05 | B52: Corporate domain and contact assurance | C52: INT-ADM-05 | F52: 500 | G52: 1200 | H52: 4000 | I52: Low | L52: =INDEX($F52:$H52,'1_Inputs'!$B$54) | M52: DNS TXT challenge, RDAP/WHOIS, MX/mailbox, domain age and reputation.
A53: A06 | B53: Signup abuse and fraud defence | C53: INT-ADM-06 | F53: 200 | G53: 600 | H53: 2500 | I53: Low | L53: =INDEX($F53:$H53,'1_Inputs'!$B$54) | M53: WAF/rate-limit/bot challenge, IP/device/email/phone/SIM and velocity intelligence at admission.
A54: A07 | B54: Contract and outsourcing due diligence | C54: INT-ADM-07 | F54: 15000 | G54: 35000 | H54: 90000 | I54: Low | L54: =INDEX($F54:$H54,'1_Inputs'!$B$54) | M54: NDA/MSA/DPA/SLA/order-form eSign, questionnaire and evidence exchange, subprocessor/BCP/DR/exit approval.
B55: TOTAL admission ₹ (one time) | L55: =SUM(L48:L54)

Sheet 4_Journey_Units_LOS
A1: 4 — Journey unit matrix: origination
A2: Units consumed per APPLICATION STARTED, before funnel attrition. This is where the 21 journeys stop being one product and become 21 different cost structures.
A3: Driver ID | B3: Cost driver | C3: personal_loan | D3: co_lending_programme | E3: msme_working_capital | F3: msme_term_loan | G3: professional_practice_loan | H3: secured_business_loan | I3: loan_against_property | J3: home_loan | K3: equipment_machinery_finance | L3: green_equipment_finance | M3: personal_vehicle_loan | N3: commercial_vehicle_finance | O3: gold_loan | P3: education_loan | Q3: agriculture_allied_finance | R3: microfinance_group_lending | S3: consumer_durable_finance | T3: invoice_discounting | U3: purchase_order_finance | V3: supply_chain_finance | W3: trade_finance_workflow
B4: Archetype | C4: unsecured_term | D4: co_lending | E4: revolving_working_capital | F4: business_term | G4: business_term | H4: property_secured | I4: property_secured | J4: property_secured | K4: asset_finance | L4: asset_finance | M4: asset_finance | N4: asset_finance | O4: gold_custody | P4: priority_term | Q4: seasonal_field | R4: group_field | S4: merchant_pos | T4: trade_receivables | U4: trade_receivables | V4: trade_receivables | W4: trade_receivables
B5: Funnel preset | C5: Digital_Unsecured | D5: Digital_Unsecured | E5: MSME_Business | F5: MSME_Business | G5: MSME_Business | H5: Secured_HighTouch | I5: Secured_HighTouch | J5: Secured_HighTouch | K5: MSME_Business | L5: MSME_Business | M5: Digital_Unsecured | N5: MSME_Business | O5: Field_Group | P5: Secured_HighTouch | Q5: Field_Group | R5: Field_Group | S5: POS_Instant | T5: MSME_Business | U5: MSME_Business | V5: MSME_Business | W5: MSME_Business
B6: Avg ticket (₹) | C6: 250000 | D6: 300000 | E6: 1500000 | F6: 1200000 | G6: 1500000 | H6: 5000000 | I6: 6000000 | J6: 4500000 | K6: 2500000 | L6: 3000000 | M6: 800000 | N6: 1800000 | O6: 150000 | P6: 1000000 | Q6: 200000 | R6: 45000 | S6: 35000 | T6: 800000 | U6: 1500000 | V6: 1000000 | W6: 3000000
B7: Units per application started ▼
A8: D01 | B8: Mobile/email OTP + delivery (DLT SMS / WhatsApp) | C8: 1 | D8: 1 | E8: 2 | F8: 2 | G8: 2 | H8: 2 | I8: 2 | J8: 2 | K8: 2 | L8: 2 | M8: 1 | N8: 2 | O8: 1 | P8: 2 | Q8: 1 | R8: 1 | S8: 1 | T8: 2 | U8: 2 | V8: 2 | W8: 2
A9: D02 | B9: Lead capture, dedupe and CRM sync | C9: 1 | D9: 1 | E9: 1 | F9: 1 | G9: 1 | H9: 1 | I9: 1 | J9: 1 | K9: 1 | L9: 1 | M9: 1 | N9: 1 | O9: 1 | P9: 1 | Q9: 1 | R9: 1 | S9: 1 | T9: 1 | U9: 1 | V9: 1 | W9: 1
A10: D03 | B10: Document upload + malware/DLP scan | C10: 4 | D10: 5 | E10: 16 | F10: 14 | G10: 10 | H10: 18 | I10: 18 | J10: 20 | K10: 16 | L10: 18 | M10: 6 | N10: 14 | O10: 2 | P10: 14 | Q10: 6 | R10: 3 | S10: 2 | T10: 12 | U10: 14 | V10: 8 | W10: 24
A11: D04 | B11: DigiLocker consent + issued-document fetch | C11: 1 | D11: 1 | E11: 1 | F11: 1 | G11: 1 | H11: 1 | I11: 1 | J11: 1 | K11: 1 | L11: 1 | M11: 1 | N11: 1 | O11: 0 | P11: 1 | Q11: 1 | R11: 0 | S11: 0 | T11: 0 | U11: 0 | V11: 0 | W11: 0
A12: D05 | B12: Device / SIM / IP fraud signal | C12: 1 | D12: 1 | E12: 1 | F12: 1 | G12: 1 | H12: 1 | I12: 1 | J12: 1 | K12: 1 | L12: 1 | M12: 1 | N12: 1 | O12: 0 | P12: 1 | Q12: 0 | R12: 0 | S12: 1 | T12: 1 | U12: 1 | V12: 1 | W12: 1
A13: D06 | B13: PAN verification (Protean/NSDL) | C13: 1 | D13: 1 | E13: 3 | F13: 3 | G13: 2 | H13: 3 | I13: 2 | J13: 2 | K13: 3 | L13: 3 | M13: 1 | N13: 2 | O13: 1 | P13: 2 | Q13: 1 | R13: 0.6 | S13: 1 | T13: 2 | U13: 2 | V13: 2 | W13: 2
A14: D07 | B14: Aadhaar offline XML / QR / KUA eKYC | C14: 1 | D14: 1 | E14: 2 | F14: 2 | G14: 1 | H14: 2 | I14: 2 | J14: 2 | K14: 2 | L14: 2 | M14: 1 | N14: 2 | O14: 1 | P14: 2 | Q14: 1 | R14: 1 | S14: 1 | T14: 1 | U14: 1 | V14: 1 | W14: 1
A15: D08 | B15: CKYC search + record download (CERSAI) | C15: 1 | D15: 1 | E15: 2 | F15: 2 | G15: 1 | H15: 2 | I15: 2 | J15: 2 | K15: 2 | L15: 2 | M15: 1 | N15: 2 | O15: 1 | P15: 2 | Q15: 1 | R15: 1 | S15: 1 | T15: 1 | U15: 1 | V15: 1 | W15: 1
A16: D09 | B16: V-CIP session (platform + agent handling time) | C16: 1 | D16: 1 | E16: 2 | F16: 2 | G16: 1 | H16: 2 | I16: 2 | J16: 2 | K16: 2 | L16: 2 | M16: 1 | N16: 1 | O16: 0 | P16: 2 | Q16: 0 | R16: 0 | S16: 0 | T16: 1 | U16: 1 | V16: 1 | W16: 1
A17: D10 | B17: Liveness / face match / spoof detection | C17: 1 | D17: 1 | E17: 2 | F17: 2 | G17: 1 | H17: 2 | I17: 2 | J17: 2 | K17: 2 | L17: 2 | M17: 1 | N17: 1 | O17: 1 | P17: 2 | Q17: 1 | R17: 1 | S17: 1 | T17: 1 | U17: 1 | V17: 1 | W17: 1
A18: D11 | B18: AML / PEP / sanctions / adverse media screen | C18: 1 | D18: 1 | E18: 4 | F18: 4 | G18: 2 | H18: 4 | I18: 3 | J18: 3 | K18: 4 | L18: 4 | M18: 1 | N18: 3 | O18: 1 | P18: 2 | Q18: 1 | R18: 1 | S18: 1 | T18: 4 | U18: 4 | V18: 3 | W18: 6
A19: D12 | B19: KYB — GSTIN / Udyam / MCA entity verification | C19: 0 | D19: 0 | E19: 1 | F19: 1 | G19: 1 | H19: 1 | I19: 0 | J19: 0 | K19: 1 | L19: 1 | M19: 0 | N19: 1 | O19: 0 | P19: 0 | Q19: 0 | R19: 0 | S19: 0 | T19: 2 | U19: 2 | V19: 2 | W19: 2
... A45: D38 | B45: Agent knowledge retrieval (vector query) | C45: 0 | D45: 0 | E45: 0 | F45: 0 | G45: 0 | H45: 0 | I45: 0 | J45: 0 | K45: 0 | L45: 0 | M45: 0 | N45: 0 | O45: 0 | P45: 0 | Q45: 0 | R45: 0 | S45: 0 | T45: 0 | U45: 0 | V45: 0 | W45: 0

Sheet 5_Journey_Units_Service
A1: 5 — Journey unit matrix: servicing, closure and collections
A2: Servicing units are per basis-unit (loan-month, EMI, loan-year, closure). Collections rows are APPLICABILITY multipliers — repossession and auction simply do not exist for an unsecured personal loan.
A3: Driver ID | B3: Cost driver | C3: personal_loan | D3: co_lending_programme | E3: msme_working_capital | F3: msme_term_loan | G3: professional_practice_loan | H3: secured_business_loan | I3: loan_against_property | J3: home_loan | K3: equipment_machinery_finance | L3: green_equipment_finance | M3: personal_vehicle_loan | N3: commercial_vehicle_finance | O3: gold_loan | P3: education_loan | Q3: agriculture_allied_finance | R3: microfinance_group_lending | S3: consumer_durable_finance | T3: invoice_discounting | U3: purchase_order_finance | V3: supply_chain_finance | W3: trade_finance_workflow
B5: Servicing units per basis-unit ▼
A6: S01 | B6: CBS / GL posting and acknowledgement | C6: 1 | D6: 1 | E6: 1 | F6: 1 | G6: 1 | H6: 1 | I6: 1 | J6: 1 | K6: 1 | L6: 1 | M6: 1 | N6: 1 | O6: 1 | P6: 1 | Q6: 1 | R6: 1 | S6: 1 | T6: 1 | U6: 1 | V6: 1 | W6: 1
A7: S02 | B7: NACH / eNACH presentment | C7: 1 | D7: 1 | E7: 1 | F7: 1 | G7: 1 | H7: 1 | I7: 1 | J7: 1 | K7: 1 | L7: 1 | M7: 1 | N7: 1 | O7: 1 | P7: 1 | Q7: 1 | R7: 1 | S7: 1 | T7: 1 | U7: 1 | V7: 1 | W7: 1
A8: S03 | B8: Bounce / return handling | C8: 1 | D8: 1 | E8: 1 | F8: 1 | G8: 1 | H8: 1 | I8: 1 | J8: 1 | K8: 1 | L8: 1 | M8: 1 | N8: 1 | O8: 1 | P8: 1 | Q8: 1 | R8: 1 | S8: 1 | T8: 1 | U8: 1 | V8: 1 | W8: 1
A9: S04 | B9: Receipt matching and reconciliation (UTR) | C9: 1 | D9: 1 | E9: 1 | F9: 1 | G9: 1 | H9: 1 | I9: 1 | J9: 1 | K9: 1 | L9: 1 | M9: 1 | N9: 1 | O9: 1 | P9: 1 | Q9: 1 | R9: 1 | S9: 1 | T9: 1 | U9: 1 | V9: 1 | W9: 1
A10: S05 | B10: Servicing notices (EMI, rate, penal, statement) | C10: 1 | D10: 1 | E10: 1 | F10: 1 | G10: 1 | H10: 1 | I10: 1 | J10: 1 | K10: 1 | L10: 1 | M10: 1 | N10: 1 | O10: 1 | P10: 1 | Q10: 1 | R10: 1 | S10: 1 | T10: 1 | U10: 1 | V10: 1 | W10: 1
A11: S06 | B11: Statement render, vault store and retention | C11: 1 | D11: 1 | E11: 1 | F11: 1 | G11: 1 | H11: 1 | I11: 1 | J11: 1 | K11: 1 | L11: 1 | M11: 1 | N11: 1 | O11: 1 | P11: 1 | Q11: 1 | R11: 0.3 | S11: 1 | T11: 1 | U11: 1 | V11: 1 | W11: 1
A12: S07 | B12: CIC credit furnishing (monthly submission) | C12: 1 | D12: 1 | E12: 1 | F12: 1 | G12: 1 | H12: 1 | I12: 1 | J12: 1 | K12: 1 | L12: 1 | M12: 1 | N12: 1 | O12: 1 | P12: 1 | Q12: 1 | R12: 1 | S12: 1 | T12: 1 | U12: 1 | V12: 1 | W12: 1
A13: S08 | B13: Ongoing KYC refresh / AA re-consent | C13: 1 | D13: 1 | E13: 1 | F13: 1 | G13: 1 | H13: 1 | I13: 1 | J13: 1 | K13: 1 | L13: 1 | M13: 1 | N13: 1 | O13: 1 | P13: 1 | Q13: 1 | R13: 1 | S13: 0.3 | T13: 1 | U13: 1 | V13: 1 | W13: 1
A14: S09 | B14: Portfolio bureau review | C14: 1 | D14: 1 | E14: 1 | F14: 1 | G14: 1 | H14: 1 | I14: 1 | J14: 1 | K14: 1 | L14: 1 | M14: 1 | N14: 1 | O14: 0.3 | P14: 1 | Q14: 1 | R14: 1 | S14: 1 | T14: 1 | U14: 1 | V14: 1 | W14: 1
A15: S10 | B15: Ongoing AML rescreen | C15: 1 | D15: 1 | E15: 1 | F15: 1 | G15: 1 | H15: 1 | I15: 1 | J15: 1 | K15: 1 | L15: 1 | M15: 1 | N15: 1 | O15: 1 | P15: 1 | Q15: 1 | R15: 1 | S15: 1 | T15: 1 | U15: 1 | V15: 1 | W15: 1
A16: S11 | B16: Insurance renewal / collateral revaluation | C16: 0 | D16: 0 | E16: 0.5 | F16: 0.4 | G16: 0 | H16: 1 | I16: 1 | J16: 1 | K16: 1 | L16: 1 | M16: 1 | N16: 1 | O16: 0 | P16: 0.4 | Q16: 0.5 | R16: 0 | S16: 0 | T16: 0 | U16: 0 | V16: 0 | W16: 0.3
A17: S12 | B17: Refund / excess / failed-disbursement reversal | C17: 1 | D17: 1 | E17: 1 | F17: 1 | G17: 1 | H17: 1 | I17: 1 | J17: 1 | K17: 1 | L17: 1 | M17: 1 | N17: 1 | O17: 1 | P17: 1 | Q17: 1 | R17: 1 | S17: 1 | T17: 1 | U17: 1 | V17: 1 | W17: 1
... A21: S16 | B21: Custody return and release acknowledgement | C21: 0 | D21: 0 | E21: 0 | F21: 0 | G21: 0 | H21: 0 | I21: 0 | J21: 0 | K21: 0 | L21: 0 | M21: 0 | N21: 0 | O21: 1 | P21: 0 | Q21: 0 | R21: 0 | S21: 0 | T21: 0 | U21: 0 | V21: 0 | W21: 0
B23: Collections applicability multiplier ▼
A24: C01 | B24: Tele-collections (dialer, IVR, agent, recording) | C24: 1 | D24: 1 | E24: 1 | F24: 1 | G24: 1 | H24: 1 | I24: 1 | J24: 1 | K24: 1 | L24: 1 | M24: 1 | N24: 1 | O24: 1 | P24: 1 | Q24: 1 | R24: 1 | S24: 1 | T24: 1 | U24: 1 | V24: 1 | W24: 1
A25: C02 | B25: Digital collection retry (UPI / link / NACH) | C25: 1 | D25: 1 | E25: 1 | F25: 1 | G25: 1 | H25: 1 | I25: 1 | J25: 1 | K25: 1 | L25: 1 | M25: 1 | N25: 1 | O25: 1 | P25: 1 | Q25: 1 | R25: 1 | S25: 1 | T25: 1 | U25: 1 | V25: 1 | W25: 1
A26: C03 | B26: Field collection visit | C26: 1 | D26: 1 | E26: 1 | F26: 1 | G26: 1 | H26: 1 | I26: 1 | J26: 1 | K26: 1 | L26: 1 | M26: 1 | N26: 1 | O26: 0.2 | P26: 1 | Q26: 1 | R26: 1.5 | S26: 0.3 | T26: 1 | U26: 1 | V26: 1 | W26: 1
A27: C04 | B27: Agency oversight, roster and invoice handling | C27: 1 | D27: 1 | E27: 1 | F27: 1 | G27: 1 | H27: 1 | I27: 1 | J27: 1 | K27: 1 | L27: 1 | M27: 1 | N27: 1 | O27: 1 | P27: 1 | Q27: 1 | R27: 1 | S27: 1 | T27: 1 | U27: 1 | V27: 1 | W27: 1
A28: C05 | B28: Legal case filing and eCourts tracking | C28: 1 | D28: 1 | E28: 1 | F28: 1 | G28: 1 | H28: 1 | I28: 1 | J28: 1 | K28: 1 | L28: 1 | M28: 1 | N28: 1 | O28: 0.1 | P28: 1 | Q28: 1 | R28: 0.1 | S28: 0.2 | T28: 1 | U28: 1 | V28: 1 | W28: 1
A29: C06 | B29: Security enforcement (notice, possession, custodian) | C29: 0 | D29: 0 | E29: 0.5 | F29: 0.4 | G29: 0 | H29: 1 | I29: 1 | J29: 1 | K29: 0.5 | L29: 0.5 | M29: 0 | N29: 0.3 | O29: 0 | P29: 0.3 | Q29: 0.2 | R29: 0 | S29: 0 | T29: 0.3 | U29: 0.3 | V29: 0.2 | W29: 0.4
A30: C07 | B30: Auction (publish, bidder KYC, certificate) | C30: 0 | D30: 0 | E30: 0.3 | F30: 0.3 | G30: 0 | H30: 1 | I30: 1 | J30: 1 | K30: 1 | L30: 1 | M30: 1 | N30: 1 | O30: 1 | P30: 0.3 | Q30: 0.2 | R30: 0 | S30: 0 | T30: 0 | U30: 0 | V30: 0 | W30: 0.2
A31: C08 | B31: Recovery proceeds handling and GL posting | C31: 1 | D31: 1 | E31: 1 | F31: 1 | G31: 1 | H31: 1 | I31: 1 | J31: 1 | K31: 1 | L31: 1 | M31: 1 | N31: 1 | O31: 1 | P31: 1 | Q31: 1 | R31: 1 | S31: 1 | T31: 1 | U31: 1 | V31: 1 | W31: 1
A32: C09 | B32: Repossession and yard management | C32: 0 | D32: 0 | E32: 0 | F32: 0 | G32: 0 | H32: 0 | I32: 0 | J32: 0 | K32: 1 | L32: 1 | M32: 1 | N32: 1 | O32: 0 | P32: 0 | Q32: 0 | R32: 0 | S32: 0 | T32: 0 | U32: 0 | V32: 0 | W32: 0

Sheet 6_Funnel_And_Lifetime
A1: 6 — Funnel, loan lifetime and derived quantities
A2: The three assumption sets that move the answer most: origination conversion, effective loan life, and the delinquency profile. Everything below the profile blocks is derived — do not edit it.
A4: Seq | B4: LOS stage | C4: Digital_Unsecured | D4: MSME_Business | E4: Secured_HighTouch | F4: Field_Group | G4: POS_Instant | H4: Note
A5: 1 | B5: application_capture | C5: 1 | D5: 1 | E5: 1 | F5: 1 | G5: 1 | H5: Everything that starts. Junk leads live here — never meter revenue on this.
A6: 2 | B6: kyc_aml | C6: 0.78 | D6: 0.85 | E6: 0.92 | F6: 0.95 | G6: 0.94 | H6: Drop-off from abandoned KYC, failed liveness and AML referrals.
A7: 3 | B7: specialist_assessment | C7: 0.68 | D7: 0.76 | E7: 0.88 | F7: 0.92 | G7: 0.9 | H7: Where bureau, AA and BSA cost is incurred — on files that may never fund.
A8: 4 | B8: credit_decision | C8: 0.62 | D8: 0.7 | E8: 0.82 | F8: 0.9 | G8: 0.88 | H8: Recommended revenue meter #1: real engine work, hard to game.
A9: 5 | B9: kfs_acceptance | C9: 0.4 | D9: 0.48 | E9: 0.62 | F9: 0.8 | G9: 0.75 | H9: The approval cliff. The gap from credit_decision is your approval rate.
A10: 6 | B10: contracting | C10: 0.35 | D10: 0.43 | E10: 0.56 | F10: 0.76 | G10: 0.7 | H10: eSign and eStamp drop-off.
A11: 7 | B11: disbursement | C11: 0.32 | D11: 0.4 | E11: 0.52 | F11: 0.74 | G11: 0.68 | H11: FUNDED RATE. Origination cost per funded loan scales inversely with this.
A12: 8 | B12: multiple | C12: 0.75 | D12: 0.8 | E12: 0.9 | F12: 0.93 | G12: 0.92 | H12: Blended reach for drivers firing across several stages (AI/agent tokens, retrieval).
B14: Funded rate (= disbursement reach) | C14: =C11 | D14: =D11 | E14: =E11 | F14: =F11 | G14: =G11
B15: Applications per funded loan | C15: =IFERROR(1/C11,0) | D15: =IFERROR(1/D11,0) | E15: =IFERROR(1/E11,0) | F15: =IFERROR(1/F11,0) | G15: =IFERROR(1/G11,0) | H15: You pay verification cost on every one of these, but bill an origination fee on only the one that funds.
A18: LOS driver reach lookup (derived)
A19: Driver ID | B19: LOS stage | C19: Digital_Unsecured | D19: MSME_Business | E19: Secured_HighTouch | F19: Field_Group | G19: POS_Instant
A20: D01 | B20: application_capture | C20: =INDEX(C$5:C$12,MATCH($B20,$B$5:$B$12,0)) | D20: =INDEX(D$5:D$12,MATCH($B20,$B$5:$B$12,0)) | E20: =INDEX(E$5:E$12,MATCH($B20,$B$5:$B$12,0)) | F20: =INDEX(F$5:F$12,MATCH($B20,$B$5:$B$12,0)) | G20: =INDEX(G$5:G$12,MATCH($B20,$B$5:$B$12,0))
A21: D02 | B21: application_capture | C21: =INDEX(C$5:C$12,MATCH($B21,$B$5:$B$12,0)) | D21: =INDEX(D$5:D$12,MATCH($B21,$B$5:$B$12,0)) | E21: =INDEX(E$5:E$12,MATCH($B21,$B$5:$B$12,0)) | F21: =INDEX(F$5:F$12,MATCH($B21,$B$5:$B$12,0)) | G21: =INDEX(G$5:G$12,MATCH($B21,$B$5:$B$12,0))
A22: D03 | B22: application_capture | C22: =INDEX(C$5:C$12,MATCH($B22,$B$5:$B$12,0)) | D22: =INDEX(D$5:D$12,MATCH($B22,$B$5:$B$12,0)) | E22: =INDEX(E$5:E$12,MATCH($B22,$B$5:$B$12,0)) | F22: =INDEX(F$5:F$12,MATCH($B22,$B$5:$B$12,0)) | G22: =INDEX(G$5:G$12,MATCH($B22,$B$5:$B$12,0))
A23: D04 | B23: application_capture | C23: =INDEX(C$5:C$12,MATCH($B23,$B$5:$B$12,0)) | D23: =INDEX(D$5:D$12,MATCH($B23,$B$5:$B$12,0)) | E23: =INDEX(E$5:E$12,MATCH($B23,$B$5:$B$12,0)) | F23: =INDEX(F$5:F$12,MATCH($B23,$B$5:$B$12,0)) | G23: =INDEX(G$5:G$12,MATCH($B23,$B$5:$B$12,0))
A24: D05 | B24: application_capture | C24: =INDEX(C$5:C$12,MATCH($B24,$B$5:$B$12,0)) | D24: =INDEX(D$5:D$12,MATCH($B24,$B$5:$B$12,0)) | E24: =INDEX(E$5:E$12,MATCH($B24,$B$5:$B$12,0)) | F24: =INDEX(F$5:F$12,MATCH($B24,$B$5:$B$12,0)) | G24: =INDEX(G$5:G$12,MATCH($B24,$B$5:$B$12,0))
A25: D06 | B25: kyc_aml | C25: =INDEX(C$5:C$12,MATCH($B25,$B$5:$B$12,0)) | D25: =INDEX(D$5:D$12,MATCH($B25,$B$5:$B$12,0)) | E25: =INDEX(E$5:E$12,MATCH($B25,$B$5:$B$12,0)) | F25: =INDEX(F$5:F$12,MATCH($B25,$B$5:$B$12,0)) | G25: =INDEX(G$5:G$12,MATCH($B25,$B$5:$B$12,0))
A26: D07 | B26: kyc_aml | C26: =INDEX(C$5:C$12,MATCH($B26,$B$5:$B$12,0)) | D26: =INDEX(D$5:D$12,MATCH($B26,$B$5:$B$12,0)) | E26: =INDEX(E$5:E$12,MATCH($B26,$B$5:$B$12,0)) | F26: =INDEX(F$5:F$12,MATCH($B26,$B$5:$B$12,0)) | G26: =INDEX(G$5:G$12,MATCH($B26,$B$5:$B$12,0))
A27: D08 | B27: kyc_aml | C27: =INDEX(C$5:C$12,MATCH($B27,$B$5:$B$12,0)) | D27: =INDEX(D$5:D$12,MATCH($B27,$B$5:$B$12,0)) | E27: =INDEX(E$5:E$12,MATCH($B27,$B$5:$B$12,0)) | F27: =INDEX(F$5:F$12,MATCH($B27,$B$5:$B$12,0)) | G27: =INDEX(G$5:G$12,MATCH($B27,$B$5:$B$12,0))
A28: D09 | B28: kyc_aml | C28: =INDEX(C$5:C$12,MATCH($B28,$B$5:$B$12,0)) | D28: =INDEX(D$5:D$12,MATCH($B28,$B$5:$B$12,0)) | E28: =INDEX(E$5:E$12,MATCH($B28,$B$5:$B$12,0)) | F28: =INDEX(F$5:F$12,MATCH($B28,$B$5:$B$12,0)) | G28: =INDEX(G$5:G$12,MATCH($B28,$B$5:$B$12,0))
A29: D10 | B29: kyc_aml | C29: =INDEX(C$5:C$12,MATCH($B29,$B$5:$B$12,0)) | D29: =INDEX(D$5:D$12,MATCH($B29,$B$5:$B$12,0)) | E29: =INDEX(E$5:E$12,MATCH($B29,$B$5:$B$12,0)) | F29: =INDEX(F$5:F$12,MATCH($B29,$B$5:$B$12,0)) | G29: =INDEX(G$5:G$12,MATCH($B29,$B$5:$B$12,0))
A30: D11 | B30: kyc_aml | C30: =INDEX(C$5:C$12,MATCH($B30,$B$5:$B$12,0)) | D30: =INDEX(D$5:D$12,MATCH($B30,$B$5:$B$12,0)) | E30: =INDEX(E$5:E$12,MATCH($B30,$B$5:$B$12,0)) | F30: =INDEX(F$5:F$12,MATCH($B30,$B$5:$B$12,0)) | G30: =INDEX(G$5:G$12,MATCH($B30,$B$5:$B$12,0))
A31: D12 | B31: kyc_aml | C31: =INDEX(C$5:C$12,MATCH($B31,$B$5:$B$12,0)) | D31: =INDEX(D$5:D$12,MATCH($B31,$B$5:$B$12,0)) | E31: =INDEX(E$5:E$12,MATCH($B31,$B$5:$B$12,0)) | F31: =INDEX(F$5:F$12,MATCH($B31,$B$5:$B$12,0)) | G31: =INDEX(G$5:G$12,MATCH($B31,$B$5:$B$12,0))
... A57: D38 | B57: multiple | C57: =INDEX(C$5:C$12,MATCH($B57,$B$5:$B$12,0)) | D57: =INDEX(D$5:D$12,MATCH($B57,$B$5:$B$12,0)) | E57: =INDEX(E$5:E$12,MATCH($B57,$B$5:$B$12,0)) | F57: =INDEX(F$5:F$12,MATCH($B57,$B$5:$B$12,0)) | G57: =INDEX(G$5:G$12,MATCH($B57,$B$5:$B$12,0))
A61: Loan lifetime profile — tenor, prepayment and delinquency (EDIT the blue cells)
A62: Journey | B62: Archetype | C62: Tenor (months) | D62: Life factor | E62: Effective life (months) | F62: Effective life (years) | G62: EMI per year | H62: EMI count | I62: Bounce rate | J62: Bounced EMIs | K62: DPD 1-30 | L62: DPD 31-90 | M62: DPD 90+ | N62: Delinq months 1-30 | O62: Delinq months 31-90 | P62: Delinq months 90+ | Q62: per_loan_month | R62: per_emi | S62: per_bounced_emi | T62: per_loan_year | U62: per_closure
A63: personal_loan | B63: unsecured_term | C63: 36 | D63: 0.85 | E63: =C63*D63 | F63: =E63/12 | G63: 12 | H63: =F63*G63 | I63: 0.055 | J63: =H63*I63 | K63: 0.04 | L63: 0.015 | M63: 0.025 | N63: =$E63*K63 | O63: =$E63*L63 | P63: =$E63*M63 | Q63: =E63 | R63: =H63 | S63: =J63 | T63: =F63 | U63: 1
A64: co_lending_programme | B64: co_lending | C64: 36 | D64: 0.85 | E64: =C64*D64 | F64: =E64/12 | G64: 12 | H64: =F64*G64 | I64: 0.055 | J64: =H64*I64 | K64: 0.042 | L64: 0.016 | M64: 0.026 | N64: =$E64*K64 | O64: =$E64*L64 | P64: =$E64*M64 | Q64: =E64 | R64: =H64 | S64: =J64 | T64: =F64 | U64: 1
A65: msme_working_capital | B65: revolving_working_capital | C65: 12 | D65: 1 | E65: =C65*D65 | F65: =E65/12 | G65: 12 | H65: =F65*G65 | I65: 0.06 | J65: =H65*I65 | K65: 0.05 | L65: 0.02 | M65: 0.03 | N65: =$E65*K65 | O65: =$E65*L65 | P65: =$E65*M65 | Q65: =E65 | R65: =H65 | S65: =J65 | T65: =F65 | U65: 1
A66: msme_term_loan | B66: business_term | C66: 48 | D66: 0.8 | E66: =C66*D66 | F66: =E66/12 | G66: 12 | H66: =F66*G66 | I66: 0.06 | J66: =H66*I66 | K66: 0.05 | L66: 0.02 | M66: 0.03 | N66: =$E66*K66 | O66: =$E66*L66 | P66: =$E66*M66 | Q66: =E66 | R66: =H66 | S66: =J66 | T66: =F66 | U66: 1
A67: professional_practice_loan | B67: business_term | C67: 60 | D67: 0.75 | E67: =C67*D67 | F67: =E67/12 | G67: 12 | H67: =F67*G67 | I67: 0.04 | J67: =H67*I67 | K67: 0.03 | L67: 0.012 | M67: 0.018 | N67: =$E67*K67 | O67: =$E67*L67 | P67: =$E67*M67 | Q67: =E67 | R67: =H67 | S67: =J67 | T67: =F67 | U67: 1
A68: secured_business_loan | B68: property_secured | C68: 120 | D68: 0.55 | E68: =C68*D68 | F68: =E68/12 | G68: 12 | H68: =F68*G68 | I68: 0.045 | J68: =H68*I68 | K68: 0.035 | L68: 0.014 | M68: 0.022 | N68: =$E68*K68 | O68: =$E68*L68 | P68: =$E68*M68 | Q68: =E68 | R68: =H68 | S68: =J68 | T68: =F68 | U68: 1
A69: loan_against_property | B69: property_secured | C69: 144 | D69: 0.5 | E69: =C69*D69 | F69: =E69/12 | G69: 12 | H69: =F69*G69 | I69: 0.04 | J69: =H69*I69 | K69: 0.03 | L69: 0.012 | M69: 0.02 | N69: =$E69*K69 | O69: =$E69*L69 | P69: =$E69*M69 | Q69: =E69 | R69: =H69 | S69: =J69 | T69: =F69 | U69: 1
A70: home_loan | B70: property_secured | C70: 240 | D70: 0.45 | E70: =C70*D70 | F70: =E70/12 | G70: 12 | H70: =F70*G70 | I70: 0.02 | J70: =H70*I70 | K70: 0.015 | L70: 0.005 | M70: 0.008 | N70: =$E70*K70 | O70: =$E70*L70 | P70: =$E70*M70 | Q70: =E70 | R70: =H70 | S70: =J70 | T70: =F70 | U70: 1
A71: equipment_machinery_finance | B71: asset_finance | C71: 60 | D71: 0.75 | E71: =C71*D71 | F71: =E71/12 | G71: 12 | H71: =F71*G71 | I71: 0.055 | J71: =H71*I71 | K71: 0.045 | L71: 0.018 | M71: 0.028 | N71: =$E71*K71 | O71: =$E71*L71 | P71: =$E71*M71 | Q71: =E71 | R71: =H71 | S71: =J71 | T71: =F71 | U71: 1
A72: green_equipment_finance | B72: asset_finance | C72: 60 | D72: 0.75 | E72: =C72*D72 | F72: =E72/12 | G72: 12 | H72: =F72*G72 | I72: 0.05 | J72: =H72*I72 | K72: 0.04 | L72: 0.016 | M72: 0.024 | N72: =$E72*K72 | O72: =$E72*L72 | P72: =$E72*M72 | Q72: =E72 | R72: =H72 | S72: =J72 | T72: =F72 | U72: 1
...

Sheet 7_Cost_Origination
A1: 7 — Origination cost engine
A2: Effective units = units per application x attempts per success x reach at the stage where the driver fires.
A3: Journey | B3: ='1_Inputs'!$B$18
A4: Journey column index | B4: ='1_Inputs'!$B$55
A5: Funnel preset | B5: =INDEX('4_Journey_Units_LOS'!$C$5:$W$5,$B$4)
A6: Funnel column index | B6: =IFERROR(MATCH($B$5,'6_Funnel_And_Lifetime'!$C$4:$G$4,0),1)
A7: Average ticket (₹) | B7: ='1_Inputs'!$B$56
A8: Rate card scenario index | B8: ='1_Inputs'!$B$54
A9: Funded rate | B9: =INDEX('6_Funnel_And_Lifetime'!$C$11:$G$11,$B$6)
A10: Decisioned rate | B10: =INDEX('6_Funnel_And_Lifetime'!$C$8:$G$8,$B$6)
A12: Driver ID | B12: Cost driver | C12: INT ID | D12: Fires at stage | E12: Units per app | F12: Attempts | G12: Stage reach | H12: Effective units / app | I12: Unit cost ₹ | J12: ₹ per application | K12: ₹ per FUNDED loan | L12: Pass-through?
A13: D01 | B13: Mobile/email OTP + delivery (DLT SMS / WhatsApp) | C13: INT-CUS-01 | D13: application_capture | E13: =INDEX('4_Journey_Units_LOS'!$C$8:$W$8,$B$4) | F13: ='2_RateCard_Unit'!$I$5 | G13: =INDEX('6_Funnel_And_Lifetime'!$C$20:$G$20,$B$6) | H13: =E13*F13*G13 | I13: =INDEX('2_RateCard_Unit'!$F$5:$H$5,$B$8) | J13: =H13*I13 | K13: =IFERROR(J13/$B$9,0) | L13: ='2_RateCard_Unit'!$K$5
A14: D02 | B14: Lead capture, dedupe and CRM sync | C14: INT-CUS-02 | D14: application_capture | E14: =INDEX('4_Journey_Units_LOS'!$C$9:$W$9,$B$4) | F14: ='2_RateCard_Unit'!$I$6 | G14: =INDEX('6_Funnel_And_Lifetime'!$C$21:$G$21,$B$6) | H14: =E14*F14*G14 | I14: =INDEX('2_RateCard_Unit'!$F$6:$H$6,$B$8) | J14: =H14*I14 | K14: =IFERROR(J14/$B$9,0) | L14: ='2_RateCard_Unit'!$K$6
A15: D03 | B15: Document upload + malware/DLP scan | C15: INT-CUS-04 | D15: application_capture | E15: =INDEX('4_Journey_Units_LOS'!$C$10:$W$10,$B$4) | F15: ='2_RateCard_Unit'!$I$7 | G15: =INDEX('6_Funnel_And_Lifetime'!$C$22:$G$22,$B$6) | H15: =E15*F15*G15 | I15: =INDEX('2_RateCard_Unit'!$F$7:$H$7,$B$8) | J15: =H15*I15 | K15: =IFERROR(J15/$B$9,0) | L15: ='2_RateCard_Unit'!$K$7
A16: D04 | B16: DigiLocker consent + issued-document fetch | C16: INT-CUS-05 | D16: application_capture | E16: =INDEX('4_Journey_Units_LOS'!$C$11:$W$11,$B$4) | F16: ='2_RateCard_Unit'!$I$8 | G16: =INDEX('6_Funnel_And_Lifetime'!$C$23:$G$23,$B$6) | H16: =E16*F16*G16 | I16: =INDEX('2_RateCard_Unit'!$F$8:$H$8,$B$8) | J16: =H16*I16 | K16: =IFERROR(J16/$B$9,0) | L16: ='2_RateCard_Unit'!$K$8
A17: D05 | B17: Device / SIM / IP fraud signal | C17: INT-LOS-09 | D17: application_capture | E17: =INDEX('4_Journey_Units_LOS'!$C$12:$W$12,$B$4) | F17: ='2_RateCard_Unit'!$I$9 | G17: =INDEX('6_Funnel_And_Lifetime'!$C$24:$G$24,$B$6) | H17: =E17*F17*G17 | I17: =INDEX('2_RateCard_Unit'!$F$9:$H$9,$B$8) | J17: =H17*I17 | K17: =IFERROR(J17/$B$9,0) | L17: ='2_RateCard_Unit'!$K$9
A18: D06 | B18: PAN verification (Protean/NSDL) | C18: INT-LOS-01 | D18: kyc_aml | E18: =INDEX('4_Journey_Units_LOS'!$C$13:$W$13,$B$4) | F18: ='2_RateCard_Unit'!$I$10 | G18: =INDEX('6_Funnel_And_Lifetime'!$C$25:$G$25,$B$6) | H18: =E18*F18*G18 | I18: =INDEX('2_RateCard_Unit'!$F$10:$H$10,$B$8) | J18: =H18*I18 | K18: =IFERROR(J18/$B$9,0) | L18: ='2_RateCard_Unit'!$K$10
A19: D07 | B19: Aadhaar offline XML / QR / KUA eKYC | C19: INT-LOS-01 | D19: kyc_aml | E19: =INDEX('4_Journey_Units_LOS'!$C$14:$W$14,$B$4) | F19: ='2_RateCard_Unit'!$I$11 | G19: =INDEX('6_Funnel_And_Lifetime'!$C$26:$G$26,$B$6) | H19: =E19*F19*G19 | I19: =INDEX('2_RateCard_Unit'!$F$11:$H$11,$B$8) | J19: =H19*I19 | K19: =IFERROR(J19/$B$9,0) | L19: ='2_RateCard_Unit'!$K$11
A20: D08 | B20: CKYC search + record download (CERSAI) | C20: INT-LOS-02 | D20: kyc_aml | E20: =INDEX('4_Journey_Units_LOS'!$C$15:$W$15,$B$4) | F20: ='2_RateCard_Unit'!$I$12 | G20: =INDEX('6_Funnel_And_Lifetime'!$C$27:$G$27,$B$6) | H20: =E20*F20*G20 | I20: =INDEX('2_RateCard_Unit'!$F$12:$H$12,$B$8) | J20: =H20*I20 | K20: =IFERROR(J20/$B$9,0) | L20: ='2_RateCard_Unit'!$K$12
A21: D09 | B21: V-CIP session (platform + agent handling time) | C21: INT-LOS-03 | D21: kyc_aml | E21: =INDEX('4_Journey_Units_LOS'!$C$16:$W$16,$B$4) | F21: ='2_RateCard_Unit'!$I$13 | G21: =INDEX('6_Funnel_And_Lifetime'!$C$28:$G$28,$B$6) | H21: =E21*F21*G21 | I21: =INDEX('2_RateCard_Unit'!$F$13:$H$13,$B$8) | J21: =H21*I21 | K21: =IFERROR(J21/$B$9,0) | L21: ='2_RateCard_Unit'!$K$13
A22: D10 | B22: Liveness / face match / spoof detection | C22: INT-LOS-03 | D22: kyc_aml | E22: =INDEX('4_Journey_Units_LOS'!$C$17:$W$17,$B$4) | F22: ='2_RateCard_Unit'!$I$14 | G22: =INDEX('6_Funnel_And_Lifetime'!$C$29:$G$29,$B$6) | H22: =E22*F22*G22 | I22: =INDEX('2_RateCard_Unit'!$F$14:$H$14,$B$8) | J22: =H22*I22 | K22: =IFERROR(J22/$B$9,0) | L22: ='2_RateCard_Unit'!$K$14
A23: D11 | B23: AML / PEP / sanctions / adverse media screen | C23: INT-LOS-09 | D23: kyc_aml | E23: =INDEX('4_Journey_Units_LOS'!$C$18:$W$18,$B$4) | F23: ='2_RateCard_Unit'!$I$15 | G23: =INDEX('6_Funnel_And_Lifetime'!$C$30:$G$30,$B$6) | H23: =E23*F23*G23 | I23: =INDEX('2_RateCard_Unit'!$F$15:$H$15,$B$8) | J23: =H23*I23 | K23: =IFERROR(J23/$B$9,0) | L23: ='2_RateCard_Unit'!$K$15
A24: D12 | B24: KYB — GSTIN / Udyam / MCA entity verification | C24: INT-LOS-04 | D24: kyc_aml | E24: =INDEX('4_Journey_Units_LOS'!$C$19:$W$19,$B$4) | F24: ='2_RateCard_Unit'!$I$16 | G24: =INDEX('6_Funnel_And_Lifetime'!$C$31:$G$31,$B$6) | H24: =E24*F24*G24 | I24: =INDEX('2_RateCard_Unit'!$F$16:$H$16,$B$8) | J24: =H24*I24 | K24: =IFERROR(J24/$B$9,0) | L24: ='2_RateCard_Unit'!$K$16
A25: D13 | B25: Director / signatory / UBO verification | C25: INT-LOS-04 | D25: kyc_aml | E25: =INDEX('4_Journey_Units_LOS'!$C$20:$W$20,$B$4) | F25: ='2_RateCard_Unit'!$I$17 | G25: =INDEX('6_Funnel_And_Lifetime'!$C$32:$G$32,$B$6) | H25: =E25*F25*G25 | I25: =INDEX('2_RateCard_Unit'!$F$17:$H$17,$B$8) | J25: =H25*I25 | K25: =IFERROR(J25/$B$9,0) | L25: ='2_RateCard_Unit'!$K$17
A26: D14 | B26: Credit bureau — consumer (CIBIL/Experian/Equifax/CRIF) | C26: INT-LOS-06 | D26: specialist_assessment | E26: =INDEX('4_Journey_Units_LOS'!$C$21:$W$21,$B$4) | F26: ='2_RateCard_Unit'!$I$18 | G26: =INDEX('6_Funnel_And_Lifetime'!$C$33:$G$33,$B$6) | H26: =E26*F26*G26 | I26: =INDEX('2_RateCard_Unit'!$F$18:$H$18,$B$8) | J26: =H26*I26 | K26: =IFERROR(J26/$B$9,0) | L26: ='2_RateCard_Unit'!$K$18
A27: D15 | B27: Credit bureau — commercial (CMR / CCR) | C27: INT-LOS-06 | D27: specialist_assessment | E27: =INDEX('4_Journey_Units_LOS'!$C$22:$W$22,$B$4) | F27: ='2_RateCard_Unit'!$I$19 | G27: =INDEX('6_Funnel_And_Lifetime'!$C$34:$G$34,$B$6) | H27: =E27*F27*G27 | I27: =INDEX('2_RateCard_Unit'!$F$19:$H$19,$B$8) | J27: =H27*I27 | K27: =IFERROR(J27/$B$9,0) | L27: ='2_RateCard_Unit'!$K$19
A28: D16 | B28: Account Aggregator consent + FI data fetch | C28: INT-LOS-07 | D28: specialist_assessment | E28: =INDEX('4_Journey_Units_LOS'!$C$23:$W$23,$B$4) | F28: ='2_RateCard_Unit'!$I$20 | G28: =INDEX('6_Funnel_And_Lifetime'!$C$35:$G$35,$B$6) | H28: =E28*F28*G28 | I28: =INDEX('2_RateCard_Unit'!$F$20:$H$20,$B$8) | J28: =H28*I28 | K28: =IFERROR(J28/$B$9,0) | L28: ='2_RateCard_Unit'!$K$20
A29: D17 | B29: Bank statement analysis (parse, tamper, categorise) | C29: INT-LOS-08 | D29: specialist_assessment | E29: =INDEX('4_Journey_Units_LOS'!$C$24:$W$24,$B$4) | F29: ='2_RateCard_Unit'!$I$21 | G29: =INDEX('6_Funnel_And_Lifetime'!$C$36:$G$36,$B$6) | H29: =E29*F29*G29 | I29: =INDEX('2_RateCard_Unit'!$F$21:$H$21,$B$8) | J29: =H29*I29 | K29: =IFERROR(J29/$B$9,0) | L29: ='2_RateCard_Unit'!$K$21
A30: D18 | B30: Income / employment evidence (EPFO, ITR, 26AS, GST) | C30: INT-LOS-05 | D30: specialist_assessment | E30: =INDEX('4_Journey_Units_LOS'!$C$25:$W$25,$B$4) | F30: ='2_RateCard_Unit'!$I$22 | G30: =INDEX('6_Funnel_And_Lifetime'!$C$37:$G$37,$B$6) | H30: =E30*F30*G30 | I30: =INDEX('2_RateCard_Unit'!$F$22:$H$22,$B$8) | J30: =H30*I30 | K30: =IFERROR(J30/$B$9,0) | L30: ='2_RateCard_Unit'!$K$22
A31: D19 | B31: OCR / document extraction + authenticity | C31: INT-LOS-10 | D31: specialist_assessment | E31: =INDEX('4_Journey_Units_LOS'!$C$26:$W$26,$B$4) | F31: ='2_RateCard_Unit'!$I$23 | G31: =INDEX('6_Funnel_And_Lifetime'!$C$38:$G$38,$B$6) | H31: =E31*F31*G31 | I31: =INDEX('2_RateCard_Unit'!$F$23:$H$23,$B$8) | J31: =H31*I31 | K31: =IFERROR(J31/$B$9,0) | L31: ='2_RateCard_Unit'!$K$23
A32: D20 | B32: Field investigation / personal discussion visit | C32: - | D32: specialist_assessment | E32: =INDEX('4_Journey_Units_LOS'!$C$27:$W$27,$B$4) | F32: ='2_RateCard_Unit'!$I$24 | G32: =INDEX('6_Funnel_And_Lifetime'!$C$39:$G$39,$B$6) | H32: =E32*F32*G32 | I32: =INDEX('2_RateCard_Unit'!$F$24:$H$24,$B$8) | J32: =H32*I32 | K32: =IFERROR(J32/$B$9,0) | L32: ='2_RateCard_Unit'!$K$24
A33: D21 | B33: Property valuation report | C33: INT-LOS-13 | D33: specialist_assessment | E33: =INDEX('4_Journey_Units_LOS'!$C$28:$W$28,$B$4) | F33: ='2_RateCard_Unit'!$I$25 | G33: =INDEX('6_Funnel_And_Lifetime'!$C$40:$G$40,$B$6) | H33: =E33*F33*G33 | I33: =INDEX('2_RateCard_Unit'!$F$25:$H$25,$B$8) | J33: =H33*I33 | K33: =IFERROR(J33/$B$9,0) | L33: ='2_RateCard_Unit'!$K$25
A34: D22 | B34: Legal / title search report | C34: INT-LOS-13 | D34: specialist_assessment | E34: =INDEX('4_Journey_Units_LOS'!$C$29:$W$29,$B$4) | F34: ='2_RateCard_Unit'!$I$26 | G34: =INDEX('6_Funnel_And_Lifetime'!$C$41:$G$41,$B$6) | H34: =E34*F34*G34 | I34: =INDEX('2_RateCard_Unit'!$F$26:$H$26,$B$8) | J34: =H34*I34 | K34: =IFERROR(J34/$B$9,0) | L34: ='2_RateCard_Unit'!$K$26
A35: D23 | B35: Asset / vehicle inspection and valuation | C35: INT-LOS-13 | D35: specialist_assessment | E35: =INDEX('4_Journey_Units_LOS'!$C$30:$W$30,$B$4) | F35: ='2_RateCard_Unit'!$I$27 | G35: =INDEX('6_Funnel_And_Lifetime'!$C$42:$G$42,$B$6) | H35: =E35*F35*G35 | I35: =INDEX('2_RateCard_Unit'!$F$27:$H$27,$B$8) | J35: =H35*I35 | K35: =IFERROR(J35/$B$9,0) | L35: ='2_RateCard_Unit'!$K$27
A36: D24 | B36: Gold assay + dual-control custody handling | C36: INT-LOS-13 | D36: specialist_assessment | E36: =INDEX('4_Journey_Units_LOS'!$C$31:$W$31,$B$4) | F36: ='2_RateCard_Unit'!$I$28 | G36: =INDEX('6_Funnel_And_Lifetime'!$C$43:$G$43,$B$6) | H36: =E36*F36*G36 | I36: =INDEX('2_RateCard_Unit'!$F$28:$H$28,$B$8) | J36: =H36*I36 | K36: =IFERROR(J36/$B$9,0) | L36: ='2_RateCard_Unit'!$K$28
A37: D25 | B37: Decision engine evaluation (per-tenant Rust runtime) | C37: - | D37: credit_decision | E37: =INDEX('4_Journey_Units_LOS'!$C$32:$W$32,$B$4) | F37: ='2_RateCard_Unit'!$I$29 | G37: =INDEX('6_Funnel_And_Lifetime'!$C$44:$G$44,$B$6) | H37: =E37*F37*G37 | I37: =INDEX('2_RateCard_Unit'!$F$29:$H$29,$B$8) | J37: =H37*I37 | K37: =IFERROR(J37/$B$9,0) | L37: ='2_RateCard_Unit'!$K$29
A38: D26 | B38: Governed AI / agent tokens and actions | C38: INT-RSK-07 | D38: multiple | E38: =INDEX('4_Journey_Units_LOS'!$C$33:$W$33,$B$4) | F38: ='2_RateCard_Unit'!$I$30 | G38: =INDEX('6_Funnel_And_Lifetime'!$C$45:$G$45,$B$6) | H38: =E38*F38*G38 | I38: =INDEX('2_RateCard_Unit'!$F$30:$H$30,$B$8) | J38: =H38*I38 | K38: =IFERROR(J38/$B$9,0) | L38: ='2_RateCard_Unit'!$K$30
A39: D27 | B39: KFS + sanction letter generation and dispatch | C39: INT-LOS-17 | D39: kfs_acceptance | E39: =INDEX('4_Journey_Units_LOS'!$C$34:$W$34,$B$4) | F39: ='2_RateCard_Unit'!$I$31 | G39: =INDEX('6_Funnel_And_Lifetime'!$C$46:$G$46,$B$6) | H39: =E39*F39*G39 | I39: =INDEX('2_RateCard_Unit'!$F$31:$H$31,$B$8) | J39: =H39*I39 | K39: =IFERROR(J39/$B$9,0) | L39: ='2_RateCard_Unit'!$K$31
A40: D28 | B40: eSign signature (Aadhaar eSign / DSC) | C40: INT-LOS-11 | D40: contracting | E40: =INDEX('4_Journey_Units_LOS'!$C$35:$W$35,$B$4) | F40: ='2_RateCard_Unit'!$I$32 | G40: =INDEX('6_Funnel_And_Lifetime'!$C$47:$G$47,$B$6) | H40: =E40*F40*G40 | I40: =INDEX('2_RateCard_Unit'!$F$32:$H$32,$B$8) | J40: =H40*I40 | K40: =IFERROR(J40/$B$9,0) | L40: ='2_RateCard_Unit'!$K$32
A41: D29 | B41: eStamp facilitation fee (duty itself excluded) | C41: INT-LOS-11 | D41: contracting | E41: =INDEX('4_Journey_Units_LOS'!$C$36:$W$36,$B$4) | F41: ='2_RateCard_Unit'!$I$33 | G41: =INDEX('6_Funnel_And_Lifetime'!$C$48:$G$48,$B$6) | H41: =E41*F41*G41 | I41: =INDEX('2_RateCard_Unit'!$F$33:$H$33,$B$8) | J41: =H41*I41 | K41: =IFERROR(J41/$B$9,0) | L41: ='2_RateCard_Unit'!$K$33
...

Sheet 8_Cost_Servicing
A1: 8 — Servicing, closure and collections cost engine
A2: Cost per funded loan over its WHOLE LIFE. Servicing units are multiplied by the basis quantity the loan generates (loan-months, EMIs, loan-years, one closure); collections events come from the delinquency profile.
A3: Journey | B3: ='1_Inputs'!$B$18
A4: Journey column index | B4: ='1_Inputs'!$B$55
A5: Lifetime row index | B5: =IFERROR(MATCH($B$3,'6_Funnel_And_Lifetime'!$A$63:$A$83,0),1)
A6: Rate card scenario index | B6: ='1_Inputs'!$B$54
A7: Effective life (months) | B7: =INDEX('6_Funnel_And_Lifetime'!$E$63:$E$83,$B$5)
A8: Effective life (years) | B8: =INDEX('6_Funnel_And_Lifetime'!$F$63:$F$83,$B$5)
A9: EMI count over life | B9: =INDEX('6_Funnel_And_Lifetime'!$H$63:$H$83,$B$5)
A10: Bounced EMIs over life | B10: =INDEX('6_Funnel_And_Lifetime'!$J$63:$J$83,$B$5)
A11: Delinquent loan-months (all buckets) | B11: =INDEX('6_Funnel_And_Lifetime'!$N$63:$N$83,$B$5)+INDEX('6_Funnel_And_Lifetime'!$O$63:$O$83,$B$5)+INDEX('6_Funnel_And_Lifetime'!$P$63:$P$83,$B$5)
A14: Driver ID | B14: Cost driver | C14: INT ID | D14: Basis | E14: Units per basis-unit | F14: Basis qty over life | G14: Attempts | H14: Unit cost ₹ | I14: ₹ per FUNDED loan (lifetime) | J14: Pass-through?
A15: S01 | B15: CBS / GL posting and acknowledgement | C15: INT-LMS-01 | D15: per_loan_month | E15: =INDEX('5_Journey_Units_Service'!$C$6:$W$6,$B$4) | F15: =INDEX('6_Funnel_And_Lifetime'!$C$104:$W$104,$B$4) | G15: ='2_RateCard_Unit'!$I$43 | H15: =INDEX('2_RateCard_Unit'!$F$43:$H$43,$B$6) | I15: =E15*F15*G15*H15 | J15: ='2_RateCard_Unit'!$K$43
A16: S02 | B16: NACH / eNACH presentment | C16: INT-LMS-03 | D16: per_emi | E16: =INDEX('5_Journey_Units_Service'!$C$7:$W$7,$B$4) | F16: =INDEX('6_Funnel_And_Lifetime'!$C$105:$W$105,$B$4) | G16: ='2_RateCard_Unit'!$I$44 | H16: =INDEX('2_RateCard_Unit'!$F$44:$H$44,$B$6) | I16: =E16*F16*G16*H16 | J16: ='2_RateCard_Unit'!$K$44
A17: S03 | B17: Bounce / return handling | C17: INT-LMS-03 | D17: per_bounced_emi | E17: =INDEX('5_Journey_Units_Service'!$C$8:$W$8,$B$4) | F17: =INDEX('6_Funnel_And_Lifetime'!$C$106:$W$106,$B$4) | G17: ='2_RateCard_Unit'!$I$45 | H17: =INDEX('2_RateCard_Unit'!$F$45:$H$45,$B$6) | I17: =E17*F17*G17*H17 | J17: ='2_RateCard_Unit'!$K$45
A18: S04 | B18: Receipt matching and reconciliation (UTR) | C18: INT-LMS-04 | D18: per_emi | E18: =INDEX('5_Journey_Units_Service'!$C$9:$W$9,$B$4) | F18: =INDEX('6_Funnel_And_Lifetime'!$C$107:$W$107,$B$4) | G18: ='2_RateCard_Unit'!$I$46 | H18: =INDEX('2_RateCard_Unit'!$F$46:$H$46,$B$6) | I18: =E18*F18*G18*H18 | J18: ='2_RateCard_Unit'!$K$46
A19: S05 | B19: Servicing notices (EMI, rate, penal, statement) | C19: INT-LMS-06 | D19: per_loan_month | E19: =INDEX('5_Journey_Units_Service'!$C$10:$W$10,$B$4) | F19: =INDEX('6_Funnel_And_Lifetime'!$C$108:$W$108,$B$4) | G19: ='2_RateCard_Unit'!$I$47 | H19: =INDEX('2_RateCard_Unit'!$F$47:$H$47,$B$6) | I19: =E19*F19*G19*H19 | J19: ='2_RateCard_Unit'!$K$47
A20: S06 | B20: Statement render, vault store and retention | C20: INT-LMS-07 | D20: per_loan_month | E20: =INDEX('5_Journey_Units_Service'!$C$11:$W$11,$B$4) | F20: =INDEX('6_Funnel_And_Lifetime'!$C$109:$W$109,$B$4) | G20: ='2_RateCard_Unit'!$I$48 | H20: =INDEX('2_RateCard_Unit'!$F$48:$H$48,$B$6) | I20: =E20*F20*G20*H20 | J20: ='2_RateCard_Unit'!$K$48
A21: S07 | B21: CIC credit furnishing (monthly submission) | C21: INT-LMS-08 | D21: per_loan_month | E21: =INDEX('5_Journey_Units_Service'!$C$12:$W$12,$B$4) | F21: =INDEX('6_Funnel_And_Lifetime'!$C$110:$W$110,$B$4) | G21: ='2_RateCard_Unit'!$I$49 | H21: =INDEX('2_RateCard_Unit'!$F$49:$H$49,$B$6) | I21: =E21*F21*G21*H21 | J21: ='2_RateCard_Unit'!$K$49
A22: S08 | B22: Ongoing KYC refresh / AA re-consent | C22: INT-LMS-09 | D22: per_loan_year | E22: =INDEX('5_Journey_Units_Service'!$C$13:$W$13,$B$4) | F22: =INDEX('6_Funnel_And_Lifetime'!$C$111:$W$111,$B$4) | G22: ='2_RateCard_Unit'!$I$50 | H22: =INDEX('2_RateCard_Unit'!$F$50:$H$50,$B$6) | I22: =E22*F22*G22*H22 | J22: ='2_RateCard_Unit'!$K$50
A23: S09 | B23: Portfolio bureau review | C23: INT-LMS-09 | D23: per_loan_year | E23: =INDEX('5_Journey_Units_Service'!$C$14:$W$14,$B$4) | F23: =INDEX('6_Funnel_And_Lifetime'!$C$112:$W$112,$B$4) | G23: ='2_RateCard_Unit'!$I$51 | H23: =INDEX('2_RateCard_Unit'!$F$51:$H$51,$B$6) | I23: =E23*F23*G23*H23 | J23: ='2_RateCard_Unit'!$K$51
A24: S10 | B24: Ongoing AML rescreen | C24: INT-LMS-09 | D24: per_loan_year | E24: =INDEX('5_Journey_Units_Service'!$C$15:$W$15,$B$4) | F24: =INDEX('6_Funnel_And_Lifetime'!$C$113:$W$113,$B$4) | G24: ='2_RateCard_Unit'!$I$52 | H24: =INDEX('2_RateCard_Unit'!$F$52:$H$52,$B$6) | I24: =E24*F24*G24*H24 | J24: ='2_RateCard_Unit'!$K$52
A25: S11 | B25: Insurance renewal / collateral revaluation | C25: INT-LMS-10 | D25: per_loan_year | E25: =INDEX('5_Journey_Units_Service'!$C$16:$W$16,$B$4) | F25: =INDEX('6_Funnel_And_Lifetime'!$C$114:$W$114,$B$4) | G25: ='2_RateCard_Unit'!$I$53 | H25: =INDEX('2_RateCard_Unit'!$F$53:$H$53,$B$6) | I25: =E25*F25*G25*H25 | J25: ='2_RateCard_Unit'!$K$53
A26: S12 | B26: Refund / excess / failed-disbursement reversal | C26: INT-LMS-05 | D26: per_loan_year | E26: =INDEX('5_Journey_Units_Service'!$C$17:$W$17,$B$4) | F26: =INDEX('6_Funnel_And_Lifetime'!$C$115:$W$115,$B$4) | G26: ='2_RateCard_Unit'!$I$54 | H26: =INDEX('2_RateCard_Unit'!$F$54:$H$54,$B$6) | I26: =E26*F26*G26*H26 | J26: ='2_RateCard_Unit'!$K$54
A27: S13 | B27: Restructure / transfer instruction | C27: INT-LMS-11 | D27: per_loan_year | E27: =INDEX('5_Journey_Units_Service'!$C$18:$W$18,$B$4) | F27: =INDEX('6_Funnel_And_Lifetime'!$C$116:$W$116,$B$4) | G27: ='2_RateCard_Unit'!$I$55 | H27: =INDEX('2_RateCard_Unit'!$F$55:$H$55,$B$6) | I27: =E27*F27*G27*H27 | J27: ='2_RateCard_Unit'!$K$55
A28: S14 | B28: Closure: mandate cancel, NOC generation and delivery | C28: INT-LMS-12 | D28: per_closure | E28: =INDEX('5_Journey_Units_Service'!$C$19:$W$19,$B$4) | F28: =INDEX('6_Funnel_And_Lifetime'!$C$117:$W$117,$B$4) | G28: ='2_RateCard_Unit'!$I$56 | H28: =INDEX('2_RateCard_Unit'!$F$56:$H$56,$B$6) | I28: =E28*F28*G28*H28 | J28: ='2_RateCard_Unit'!$K$56
A29: S15 | B29: Security registry satisfaction (CERSAI / ROC / RTO) | C29: INT-COLAT-04 | D29: per_closure | E29: =INDEX('5_Journey_Units_Service'!$C$20:$W$20,$B$4) | F29: =INDEX('6_Funnel_And_Lifetime'!$C$118:$W$118,$B$4) | G29: ='2_RateCard_Unit'!$I$57 | H29: =INDEX('2_RateCard_Unit'!$F$57:$H$57,$B$6) | I29: =E29*F29*G29*H29 | J29: ='2_RateCard_Unit'!$K$57
